[2022-02-09 18:47:06,390] {taskinstance.py:896} INFO - Dependencies all met for <TaskInstance: hello_world.spark_job 2022-02-09T18:46:48.692700+00:00 [queued]>
[2022-02-09 18:47:06,424] {taskinstance.py:896} INFO - Dependencies all met for <TaskInstance: hello_world.spark_job 2022-02-09T18:46:48.692700+00:00 [queued]>
[2022-02-09 18:47:06,482] {taskinstance.py:896} INFO - Dependencies all met for <TaskInstance: hello_world.spark_job 2022-02-09T18:46:48.692700+00:00 [queued]>
[2022-02-09 18:47:06,482] {taskinstance.py:896} INFO - Dependencies all met for <TaskInstance: hello_world.spark_job 2022-02-09T18:46:48.692700+00:00 [queued]>
[2022-02-09 18:47:06,482] {taskinstance.py:1087} INFO - 
--------------------------------------------------------------------------------
[2022-02-09 18:47:06,482] {taskinstance.py:1087} INFO - 
--------------------------------------------------------------------------------
[2022-02-09 18:47:06,482] {taskinstance.py:1088} INFO - Starting attempt 1 of 1
[2022-02-09 18:47:06,483] {taskinstance.py:1088} INFO - Starting attempt 1 of 1
[2022-02-09 18:47:06,483] {taskinstance.py:1089} INFO - 
--------------------------------------------------------------------------------
[2022-02-09 18:47:06,483] {taskinstance.py:1089} INFO - 
--------------------------------------------------------------------------------
[2022-02-09 18:47:06,536] {taskinstance.py:1107} INFO - Executing <Task(SparkSubmitOperator): spark_job> on 2022-02-09T18:46:48.692700+00:00
[2022-02-09 18:47:06,546] {standard_task_runner.py:52} INFO - Started process 46 to run task
[2022-02-09 18:47:06,554] {standard_task_runner.py:76} INFO - Running: ['***', 'tasks', 'run', 'hello_world', 'spark_job', '2022-02-09T18:46:48.692700+00:00', '--job-id', '32', '--pool', 'default_pool', '--raw', '--subdir', 'DAGS_FOLDER/task.py', '--cfg-path', '/tmp/tmpoqbq24kc', '--error-file', '/tmp/tmp52ej35o9']
[2022-02-09 18:47:06,554] {standard_task_runner.py:77} INFO - Job 32: Subtask spark_job
[2022-02-09 18:47:06,692] {taskinstance.py:1107} INFO - Executing <Task(SparkSubmitOperator): spark_job> on 2022-02-09T18:46:48.692700+00:00
[2022-02-09 18:47:06,699] {standard_task_runner.py:52} INFO - Started process 47 to run task
[2022-02-09 18:47:06,706] {standard_task_runner.py:76} INFO - Running: ['***', 'tasks', 'run', 'hello_world', 'spark_job', '2022-02-09T18:46:48.692700+00:00', '--job-id', '31', '--pool', 'default_pool', '--raw', '--subdir', 'DAGS_FOLDER/task.py', '--cfg-path', '/tmp/tmpjvwozt9p', '--error-file', '/tmp/tmp9h0ft2ov']
[2022-02-09 18:47:06,707] {standard_task_runner.py:77} INFO - Job 31: Subtask spark_job
[2022-02-09 18:47:07,730] {logging_mixin.py:104} INFO - Running <TaskInstance: hello_world.spark_job 2022-02-09T18:46:48.692700+00:00 [running]> on host 74d5157b6211
[2022-02-09 18:47:07,751] {logging_mixin.py:104} INFO - Running <TaskInstance: hello_world.spark_job 2022-02-09T18:46:48.692700+00:00 [running]> on host 74d5157b6211
[2022-02-09 18:47:08,284] {taskinstance.py:1300} INFO - Exporting the following env vars:
AIRFLOW_CTX_DAG_OWNER=admin
AIRFLOW_CTX_DAG_ID=hello_world
AIRFLOW_CTX_TASK_ID=spark_job
AIRFLOW_CTX_EXECUTION_DATE=2022-02-09T18:46:48.692700+00:00
AIRFLOW_CTX_DAG_RUN_ID=manual__2022-02-09T18:46:48.692700+00:00
[2022-02-09 18:47:08,402] {base.py:69} INFO - Using connection to: id: spark_default. Host: spark://spark, Port: 7077, Schema: , Login: ***, Password: ***, extra: {'queue': 'root.default'}
[2022-02-09 18:47:08,404] {spark_submit.py:360} INFO - Spark-Submit cmd: spark-submit --master spark://spark:7077 --conf master=spark://spark:7077 --name test --verbose --queue root.default /opt/bitnami/spark/app/test.py
[2022-02-09 18:47:08,340] {taskinstance.py:1501} ERROR - Task failed with exception
Traceback (most recent call last):
  File "/home/airflow/.local/lib/python3.8/site-packages/sqlalchemy/engine/base.py", line 1276, in _execute_context
    self.dialect.do_execute(
  File "/home/airflow/.local/lib/python3.8/site-packages/sqlalchemy/engine/default.py", line 608, in do_execute
    cursor.execute(statement, parameters)
psycopg2.errors.UniqueViolation: duplicate key value violates unique constraint "rendered_task_instance_fields_pkey"
DETAIL:  Key (dag_id, task_id, execution_date)=(hello_world, spark_job, 2022-02-09 18:46:48.6927+00) already exists.


The above exception was the direct cause of the following exception:

Traceback (most recent call last):
  File "/home/airflow/.local/lib/python3.8/site-packages/airflow/models/taskinstance.py", line 1157, in _run_raw_task
    self._prepare_and_execute_task_with_callbacks(context, task)
  File "/home/airflow/.local/lib/python3.8/site-packages/airflow/models/taskinstance.py", line 1295, in _prepare_and_execute_task_with_callbacks
    RenderedTaskInstanceFields.write(RenderedTaskInstanceFields(ti=self, render_templates=False))
  File "/home/airflow/.local/lib/python3.8/site-packages/airflow/utils/session.py", line 70, in wrapper
    return func(*args, session=session, **kwargs)
  File "/usr/local/lib/python3.8/contextlib.py", line 120, in __exit__
    next(self.gen)
  File "/home/airflow/.local/lib/python3.8/site-packages/airflow/utils/session.py", line 32, in create_session
    session.commit()
  File "/home/airflow/.local/lib/python3.8/site-packages/sqlalchemy/orm/session.py", line 1046, in commit
    self.transaction.commit()
  File "/home/airflow/.local/lib/python3.8/site-packages/sqlalchemy/orm/session.py", line 504, in commit
    self._prepare_impl()
  File "/home/airflow/.local/lib/python3.8/site-packages/sqlalchemy/orm/session.py", line 483, in _prepare_impl
    self.session.flush()
  File "/home/airflow/.local/lib/python3.8/site-packages/sqlalchemy/orm/session.py", line 2540, in flush
    self._flush(objects)
  File "/home/airflow/.local/lib/python3.8/site-packages/sqlalchemy/orm/session.py", line 2682, in _flush
    transaction.rollback(_capture_exception=True)
  File "/home/airflow/.local/lib/python3.8/site-packages/sqlalchemy/util/langhelpers.py", line 68, in __exit__
    compat.raise_(
  File "/home/airflow/.local/lib/python3.8/site-packages/sqlalchemy/util/compat.py", line 182, in raise_
    raise exception
  File "/home/airflow/.local/lib/python3.8/site-packages/sqlalchemy/orm/session.py", line 2642, in _flush
    flush_context.execute()
  File "/home/airflow/.local/lib/python3.8/site-packages/sqlalchemy/orm/unitofwork.py", line 422, in execute
    rec.execute(self)
  File "/home/airflow/.local/lib/python3.8/site-packages/sqlalchemy/orm/unitofwork.py", line 586, in execute
    persistence.save_obj(
  File "/home/airflow/.local/lib/python3.8/site-packages/sqlalchemy/orm/persistence.py", line 239, in save_obj
    _emit_insert_statements(
  File "/home/airflow/.local/lib/python3.8/site-packages/sqlalchemy/orm/persistence.py", line 1083, in _emit_insert_statements
    c = cached_connections[connection].execute(statement, multiparams)
  File "/home/airflow/.local/lib/python3.8/site-packages/sqlalchemy/engine/base.py", line 1011, in execute
    return meth(self, multiparams, params)
  File "/home/airflow/.local/lib/python3.8/site-packages/sqlalchemy/sql/elements.py", line 298, in _execute_on_connection
    return connection._execute_clauseelement(self, multiparams, params)
  File "/home/airflow/.local/lib/python3.8/site-packages/sqlalchemy/engine/base.py", line 1124, in _execute_clauseelement
    ret = self._execute_context(
  File "/home/airflow/.local/lib/python3.8/site-packages/sqlalchemy/engine/base.py", line 1316, in _execute_context
    self._handle_dbapi_exception(
  File "/home/airflow/.local/lib/python3.8/site-packages/sqlalchemy/engine/base.py", line 1510, in _handle_dbapi_exception
    util.raise_(
  File "/home/airflow/.local/lib/python3.8/site-packages/sqlalchemy/util/compat.py", line 182, in raise_
    raise exception
  File "/home/airflow/.local/lib/python3.8/site-packages/sqlalchemy/engine/base.py", line 1276, in _execute_context
    self.dialect.do_execute(
  File "/home/airflow/.local/lib/python3.8/site-packages/sqlalchemy/engine/default.py", line 608, in do_execute
    cursor.execute(statement, parameters)
sqlalchemy.exc.IntegrityError: (psycopg2.errors.UniqueViolation) duplicate key value violates unique constraint "rendered_task_instance_fields_pkey"
DETAIL:  Key (dag_id, task_id, execution_date)=(hello_world, spark_job, 2022-02-09 18:46:48.6927+00) already exists.

[SQL: INSERT INTO rendered_task_instance_fields (dag_id, task_id, execution_date, rendered_fields, k8s_pod_yaml) VALUES (%(dag_id)s, %(task_id)s, %(execution_date)s, %(rendered_fields)s, %(k8s_pod_yaml)s)]
[parameters: {'dag_id': 'hello_world', 'task_id': 'spark_job', 'execution_date': DateTime(2022, 2, 9, 18, 46, 48, 692700, tzinfo=Timezone('UTC')), 'rendered_fields': '{"_application": "/opt/bitnami/spark/app/test.py", "_conf": {"master": "spark://spark:7077"}, "_files": null, "_py_files": null, "_jars": null, "_dri ... (40 characters truncated) ... , "_exclude_packages": null, "_keytab": null, "_principal": null, "_proxy_user": null, "_name": "test", "_application_args": null, "_env_vars": null}', 'k8s_pod_yaml': 'null'}]
(Background on this error at: http://sqlalche.me/e/13/gkpj)
[2022-02-09 18:47:08,889] {taskinstance.py:1544} INFO - Marking task as FAILED. dag_id=hello_world, task_id=spark_job, execution_date=20220209T184648, start_date=20220209T184706, end_date=20220209T184708
[2022-02-09 18:47:09,104] {local_task_job.py:151} INFO - Task exited with return code 1
[2022-02-09 18:47:11,845] {local_task_job.py:198} WARNING - State of this instance has been externally set to failed. Terminating instance.
[2022-02-09 18:47:11,851] {process_utils.py:100} INFO - Sending Signals.SIGTERM to GPID 47
[2022-02-09 18:47:11,852] {taskinstance.py:1284} ERROR - Received SIGTERM. Terminating subprocesses.
[2022-02-09 18:47:11,886] {process_utils.py:66} INFO - Process psutil.Process(pid=47, status='terminated', exitcode=0, started='18:47:06') (47) terminated with exit code 0
[2022-02-09 18:47:11,980] {process_utils.py:66} INFO - Process psutil.Process(pid=54, status='terminated', started='18:47:08') (54) terminated with exit code None
[2022-02-09 18:47:11,981] {process_utils.py:66} INFO - Process psutil.Process(pid=53, status='terminated', started='18:47:08') (53) terminated with exit code None
[2022-02-09 18:47:11,981] {process_utils.py:66} INFO - Process psutil.Process(pid=48, status='terminated', started='18:47:08') (48) terminated with exit code None
