[2022-02-11 15:54:09,714] {taskinstance.py:896} INFO - Dependencies all met for <TaskInstance: spark_first_run.spark_connection 2022-02-10T00:00:00+00:00 [queued]>
[2022-02-11 15:54:09,752] {taskinstance.py:896} INFO - Dependencies all met for <TaskInstance: spark_first_run.spark_connection 2022-02-10T00:00:00+00:00 [queued]>
[2022-02-11 15:54:09,752] {taskinstance.py:1087} INFO - 
--------------------------------------------------------------------------------
[2022-02-11 15:54:09,752] {taskinstance.py:1088} INFO - Starting attempt 1 of 4
[2022-02-11 15:54:09,752] {taskinstance.py:1089} INFO - 
--------------------------------------------------------------------------------
[2022-02-11 15:54:09,776] {taskinstance.py:1107} INFO - Executing <Task(PythonOperator): spark_connection> on 2022-02-10T00:00:00+00:00
[2022-02-11 15:54:09,782] {standard_task_runner.py:52} INFO - Started process 182 to run task
[2022-02-11 15:54:09,789] {standard_task_runner.py:76} INFO - Running: ['***', 'tasks', 'run', 'spark_first_run', 'spark_connection', '2022-02-10T00:00:00+00:00', '--job-id', '105', '--pool', 'default_pool', '--raw', '--subdir', 'DAGS_FOLDER/deploy_structure.py', '--cfg-path', '/tmp/tmpws2q5ss4', '--error-file', '/tmp/tmp4_q_nsnw']
[2022-02-11 15:54:09,789] {standard_task_runner.py:77} INFO - Job 105: Subtask spark_connection
[2022-02-11 15:54:09,885] {logging_mixin.py:104} INFO - Running <TaskInstance: spark_first_run.spark_connection 2022-02-10T00:00:00+00:00 [running]> on host e7f322c1f7d3
[2022-02-11 15:54:09,987] {taskinstance.py:1300} INFO - Exporting the following env vars:
AIRFLOW_CTX_DAG_OWNER=admin
AIRFLOW_CTX_DAG_ID=spark_first_run
AIRFLOW_CTX_TASK_ID=spark_connection
AIRFLOW_CTX_EXECUTION_DATE=2022-02-10T00:00:00+00:00
AIRFLOW_CTX_DAG_RUN_ID=scheduled__2022-02-10T00:00:00+00:00
[2022-02-11 15:54:10,004] {crypto.py:82} WARNING - empty cryptography key - values will not be stored encrypted.
[2022-02-11 15:54:10,098] {taskinstance.py:1501} ERROR - Task failed with exception
Traceback (most recent call last):
  File "/home/airflow/.local/lib/python3.8/site-packages/sqlalchemy/engine/base.py", line 1276, in _execute_context
    self.dialect.do_execute(
  File "/home/airflow/.local/lib/python3.8/site-packages/sqlalchemy/engine/default.py", line 608, in do_execute
    cursor.execute(statement, parameters)
psycopg2.errors.UniqueViolation: duplicate key value violates unique constraint "unique_conn_id"
DETAIL:  Key (conn_id)=(spark_default) already exists.


The above exception was the direct cause of the following exception:

Traceback (most recent call last):
  File "/home/airflow/.local/lib/python3.8/site-packages/airflow/models/taskinstance.py", line 1157, in _run_raw_task
    self._prepare_and_execute_task_with_callbacks(context, task)
  File "/home/airflow/.local/lib/python3.8/site-packages/airflow/models/taskinstance.py", line 1331, in _prepare_and_execute_task_with_callbacks
    result = self._execute_task(context, task_copy)
  File "/home/airflow/.local/lib/python3.8/site-packages/airflow/models/taskinstance.py", line 1361, in _execute_task
    result = task_copy.execute(context=context)
  File "/home/airflow/.local/lib/python3.8/site-packages/airflow/operators/python.py", line 150, in execute
    return_value = self.execute_callable()
  File "/home/airflow/.local/lib/python3.8/site-packages/airflow/operators/python.py", line 161, in execute_callable
    return self.python_callable(*self.op_args, **self.op_kwargs)
  File "/opt/airflow/dags/deploy_structure.py", line 28, in deploy_spark_connection
    session.commit()
  File "/home/airflow/.local/lib/python3.8/site-packages/sqlalchemy/orm/session.py", line 1046, in commit
    self.transaction.commit()
  File "/home/airflow/.local/lib/python3.8/site-packages/sqlalchemy/orm/session.py", line 504, in commit
    self._prepare_impl()
  File "/home/airflow/.local/lib/python3.8/site-packages/sqlalchemy/orm/session.py", line 483, in _prepare_impl
    self.session.flush()
  File "/home/airflow/.local/lib/python3.8/site-packages/sqlalchemy/orm/session.py", line 2540, in flush
    self._flush(objects)
  File "/home/airflow/.local/lib/python3.8/site-packages/sqlalchemy/orm/session.py", line 2682, in _flush
    transaction.rollback(_capture_exception=True)
  File "/home/airflow/.local/lib/python3.8/site-packages/sqlalchemy/util/langhelpers.py", line 68, in __exit__
    compat.raise_(
  File "/home/airflow/.local/lib/python3.8/site-packages/sqlalchemy/util/compat.py", line 182, in raise_
    raise exception
  File "/home/airflow/.local/lib/python3.8/site-packages/sqlalchemy/orm/session.py", line 2642, in _flush
    flush_context.execute()
  File "/home/airflow/.local/lib/python3.8/site-packages/sqlalchemy/orm/unitofwork.py", line 422, in execute
    rec.execute(self)
  File "/home/airflow/.local/lib/python3.8/site-packages/sqlalchemy/orm/unitofwork.py", line 586, in execute
    persistence.save_obj(
  File "/home/airflow/.local/lib/python3.8/site-packages/sqlalchemy/orm/persistence.py", line 239, in save_obj
    _emit_insert_statements(
  File "/home/airflow/.local/lib/python3.8/site-packages/sqlalchemy/orm/persistence.py", line 1135, in _emit_insert_statements
    result = cached_connections[connection].execute(
  File "/home/airflow/.local/lib/python3.8/site-packages/sqlalchemy/engine/base.py", line 1011, in execute
    return meth(self, multiparams, params)
  File "/home/airflow/.local/lib/python3.8/site-packages/sqlalchemy/sql/elements.py", line 298, in _execute_on_connection
    return connection._execute_clauseelement(self, multiparams, params)
  File "/home/airflow/.local/lib/python3.8/site-packages/sqlalchemy/engine/base.py", line 1124, in _execute_clauseelement
    ret = self._execute_context(
  File "/home/airflow/.local/lib/python3.8/site-packages/sqlalchemy/engine/base.py", line 1316, in _execute_context
    self._handle_dbapi_exception(
  File "/home/airflow/.local/lib/python3.8/site-packages/sqlalchemy/engine/base.py", line 1510, in _handle_dbapi_exception
    util.raise_(
  File "/home/airflow/.local/lib/python3.8/site-packages/sqlalchemy/util/compat.py", line 182, in raise_
    raise exception
  File "/home/airflow/.local/lib/python3.8/site-packages/sqlalchemy/engine/base.py", line 1276, in _execute_context
    self.dialect.do_execute(
  File "/home/airflow/.local/lib/python3.8/site-packages/sqlalchemy/engine/default.py", line 608, in do_execute
    cursor.execute(statement, parameters)
sqlalchemy.exc.IntegrityError: (psycopg2.errors.UniqueViolation) duplicate key value violates unique constraint "unique_conn_id"
DETAIL:  Key (conn_id)=(spark_default) already exists.

[SQL: INSERT INTO connection (conn_id, conn_type, description, host, schema, login, password, port, is_encrypted, is_extra_encrypted, extra) VALUES (%(conn_id)s, %(conn_type)s, %(description)s, %(host)s, %(schema)s, %(login)s, %(password)s, %(port)s, %(is_encrypted)s, %(is_extra_encrypted)s, %(extra)s) RETURNING connection.id]
[parameters: {'conn_id': 'spark_default', 'conn_type': 'Spark', 'description': 'connection to spark container', 'host': 'spark://spark', 'schema': None, 'login': None, 'password': None, 'port': 7077, 'is_encrypted': False, 'is_extra_encrypted': False, 'extra': '{"queue": "root.default"}'}]
(Background on this error at: http://sqlalche.me/e/13/gkpj)
[2022-02-11 15:54:10,383] {taskinstance.py:1544} INFO - Marking task as UP_FOR_RETRY. dag_id=spark_first_run, task_id=spark_connection, execution_date=20220210T000000, start_date=20220211T155409, end_date=20220211T155410
[2022-02-11 15:54:10,448] {logging_mixin.py:104} WARNING - /home/***/.local/lib/python3.8/site-packages/sqlalchemy/orm/session.py:561 SAWarning: Session's state has been changed on a non-active transaction - this state will be discarded.
[2022-02-11 15:54:10,485] {local_task_job.py:151} INFO - Task exited with return code 1
